<mujoco model="tri_finger_hand">
  <compiler angle="radian" meshdir="assets" autolimits="true"/>
  <option cone="elliptic" impratio="10"/>

  <default>
    <default class="tri_finger_hand">
      <joint axis="0 1 0" damping="0.1"/>
      <position kp="1"/>
      <geom density="800"/>
      
      <default class="visual">
        <geom type="mesh" contype="0" conaffinity="0" group="2" material="black"/>
        <default class="base_visual"><geom mesh="link_0.0"/></default>
        <default class="proximal_visual"><geom mesh="link_1.0"/></default>
        <default class="medial_visual"><geom mesh="link_2.0"/></default>
        <default class="distal_visual"><geom mesh="link_3.0"/></default>
        <default class="fingertip_visual"><geom pos="0 0 0.0267" material="white" mesh="link_3.0_tip"/></default>
      </default>

      <default class="collision">
        <geom group="3" type="box" mass="0.1"/>
        <default class="base_collision"><geom size="0.0098 0.01375 0.0082" pos="0 0 0.0082"/></default>
        <default class="proximal_collision"><geom size="0.0098 0.01375 0.027" pos="0 0 0.027"/></default>
        <default class="medial_collision"><geom size="0.0098 0.01375 0.0192" pos="0 0 0.0192"/></default>
        <default class="distal_collision"><geom size="0.0098 0.01375 0.008" pos="0 0 0.008"/></default>
        <default class="fingertip_collision"><geom type="capsule" size="0.012 0.01" pos="0 0 0.019"/></default>
      </default>

      <default class="base"><joint axis="0 0 1" range="-0.47 0.47"/><position ctrlrange="-0.47 0.47"/></default>
      <default class="proximal"><joint range="-0.196 1.61"/><position ctrlrange="-0.196 1.61"/></default>
      <default class="medial"><joint range="-0.174 1.709"/><position ctrlrange="-0.174 1.709"/></default>
      <default class="distal"><joint range="-0.227 1.618"/><position ctrlrange="-0.227 1.618"/></default>
    </default>
  </default>

  <asset>
    <material name="black" rgba="0.2 0.2 0.2 1"/>
    <material name="white" rgba="0.9 0.9 0.9 1"/>
    <mesh file="link_0.0.stl"/>
    <mesh file="link_1.0.stl"/>
    <mesh file="link_2.0.stl"/>
    <mesh file="link_3.0.stl"/>
    <mesh file="link_3.0_tip.stl"/>
  </asset>

  <worldbody>
    <body name="palm" pos="0 0 0.02" childclass="tri_finger_hand">
      <!-- Finger 1 (0 deg) -->
      <body name="f1_base" pos="0.03 0 0" quat="1 0 0 0">
        <joint name="f1j0" class="base"/>
        <geom class="base_visual"/>
        <geom class="base_collision"/>
        <body name="f1_proximal" pos="0 0 0.0164">
          <joint name="f1j1" class="proximal"/>
          <geom class="proximal_visual"/>
          <geom class="proximal_collision"/>
          <body name="f1_medial" pos="0 0 0.054">
            <joint name="f1j2" class="medial"/>
            <geom class="medial_visual"/>
            <geom class="medial_collision"/>
            <body name="f1_distal" pos="0 0 0.0384">
              <joint name="f1j3" class="distal"/>
              <geom class="distal_visual"/>
              <geom class="distal_collision"/>
              <body name="f1_tip">
                <geom class="fingertip_visual"/>
                <geom class="fingertip_collision"/>
              </body>
            </body>
          </body>
        </body>
      </body>
      <!-- Finger 2 (120 deg) -->
      <body name="f2_base" pos="-0.015 0.02598 0" quat="0.866 0 0 0.5">
        <joint name="f2j0" class="base"/>
        <geom class="base_visual"/>
        <geom class="base_collision"/>
        <body name="f2_proximal" pos="0 0 0.0164">
          <joint name="f2j1" class="proximal"/>
          <geom class="proximal_visual"/>
          <geom class="proximal_collision"/>
          <body name="f2_medial" pos="0 0 0.054">
            <joint name="f2j2" class="medial"/>
            <geom class="medial_visual"/>
            <geom class="medial_collision"/>
            <body name="f2_distal" pos="0 0 0.0384">
              <joint name="f2j3" class="distal"/>
              <geom class="distal_visual"/>
              <geom class="distal_collision"/>
              <body name="f2_tip">
                <geom class="fingertip_visual"/>
                <geom class="fingertip_collision"/>
              </body>
            </body>
          </body>
        </body>
      </body>
      <!-- Finger 3 (240 deg) -->
      <body name="f3_base" pos="-0.015 -0.02598 0" quat="0.866 0 0 -0.5">
        <joint name="f3j0" class="base"/>
        <geom class="base_visual"/>
        <geom class="base_collision"/>
        <body name="f3_proximal" pos="0 0 0.0164">
          <joint name="f3j1" class="proximal"/>
          <geom class="proximal_visual"/>
          <geom class="proximal_collision"/>
          <body name="f3_medial" pos="0 0 0.054">
            <joint name="f3j2" class="medial"/>
            <geom class="medial_visual"/>
            <geom class="medial_collision"/>
            <body name="f3_distal" pos="0 0 0.0384">
              <joint name="f3j3" class="distal"/>
              <geom class="distal_visual"/>
              <geom class="distal_collision"/>
              <body name="f3_tip">
                <geom class="fingertip_visual"/>
                <geom class="fingertip_collision"/>
              </body>
            </body>
          </body>
        </body>
      </body>
    </body>
  </worldbody>

  <actuator>
    <position name="f1a0" joint="f1j0" class="base"/>
    <position name="f1a1" joint="f1j1" class="proximal"/>
    <position name="f1a2" joint="f1j2" class="medial"/>
    <position name="f1a3" joint="f1j3" class="distal"/>
    <position name="f2a0" joint="f2j0" class="base"/>
    <position name="f2a1" joint="f2j1" class="proximal"/>
    <position name="f2a2" joint="f2j2" class="medial"/>
    <position name="f2a3" joint="f2j3" class="distal"/>
    <position name="f3a0" joint="f3j0" class="base"/>
    <position name="f3a1" joint="f3j1" class="proximal"/>
    <position name="f3a2" joint="f3j2" class="medial"/>
    <position name="f3a3" joint="f3j3" class="distal"/>
  </actuator>
</mujoco>